Workbook

Sheet DADOS_RM_SITUACAO
A1: CODCLIENTE | B1: DESCRICAO
A2: A | B2: Ativo
A3: C | B3: Contrato de Trabalho Suspenso
A4: D | B4: Demitido
A5: E | B5: Licença Mater.
A6: F | B6: Férias
A7: G | B7: Recesso Remunerado de Estagio
A8: I | B8: Apos. por Incapacidade Permanente
A9: K | B9: Cessão / Requisição
A10: L | B10: Licença s/venc
A11: M | B11: Serv.Militar
A12: N | B12: Mandato Sindical Ônus do Empregador
... A24: Z | B24: Admissão prox.mês

Sheet DADOS_RM_EVENTOS_original
A1: CODIGO | B1: DESCRICAO | C1: TIPOEVENTO | D1: VALHORDIAREF | E1: NAT_ESOCIAL | F1: CONFERE COD | H1: CONFERE DESCR
A2: 0001 | B2: Salario Base em Horas | C2: PROVENTO | D2: HORA | E2: 1000-Salario, vencimento, soldo | F2: 0001 | G2: =IF(F2=A2,1,FALSE) -> 1 | H2: SALARIO BASE EM HORAS | I2: =IF(H2=B2,1,FALSE) -> 1
A3: 0002 | B3: Salario Base em Dias | C3: PROVENTO | D3: DIA | E3: 1000-Salario, vencimento, soldo | F3: 0002 | G3: =IF(F3=A3,1,FALSE) -> 1 | H3: SALARIO BASE EM DIAS | I3: =IF(H3=B3,1,FALSE) -> 1
A4: 0003 | B4: Desc. INSS Segurado | C4: DESCONTO | D4: VALOR | E4: 9201-Contribuicao Previdenciaria | F4: 0003 | G4: =IF(F4=A4,1,FALSE) -> 1 | H4: DESC. INSS SEGURADO | I4: =IF(H4=B4,1,FALSE) -> 1
A5: 0004 | B5: Desc. IRRF na Fonte | C5: DESCONTO | D5: VALOR | E5: 9203-Imposto de renda retido na fonte | F5: 0004 | G5: =IF(F5=A5,1,FALSE) -> 1 | H5: DESC. IRRF NA FONTE | I5: =IF(H5=B5,1,FALSE) -> 1
A6: 0005 | B6: Cota de Salario Familia | C6: PROVENTO | D6: VALOR | E6: 1409-Salario familia | F6: 0005 | G6: =IF(F6=A6,1,FALSE) -> 1 | H6: COTA DE SALARIO FAMILIA | I6: =IF(H6=B6,1,FALSE) -> 1
A7: 0006 | B7: Desc. Vale Transporte | C7: DESCONTO | D7: VALOR | E7: 9216-Desconto de valetransporte | F7: 0006 | G7: =IF(F7=A7,1,FALSE) -> 1 | H7: DESC. VALE TRANSPORTE | I7: =IF(H7=B7,1,FALSE) -> 1
A8: 0007 | B8: Adicional de Penosidade | C8: PROVENTO | D8: VALOR | E8: 1214-Adicional de penosidade | F8: 0007 | G8: =IF(F8=A8,1,FALSE) -> 1 | H8: ADICIONAL DE PENOSIDADE | I8: =IF(H8=B8,1,FALSE) -> 1
A9: 0008 | B9: Desc. Faltas (em Dias) | C9: DESCONTO | D9: DIA | E9: 9209-Faltas ou atrasos | F9: 0008 | G9: =IF(F9=A9,1,FALSE) -> 1 | H9: DESC. FALTAS (EM DIAS) | I9: =IF(H9=B9,1,FALSE) -> 1
A10: 0009 | B10: 1ª Parcela 13º Salario | C10: PROVENTO | D10: VALOR | E10: 5504-13º salario ¿ Adiantamento | F10: 0009 | G10: =IF(F10=A10,1,FALSE) -> 1 | H10: 1ª PARCELA 13º SALARIO | I10: =IF(H10=B10,1,FALSE) -> 1
A11: 0010 | B11: Reflexo Sobre Escala | C11: PROVENTO | D11: VALOR | E11: 1012-Descanso semanal remunerado - DSR e feriado | F11: 0010 | G11: =IF(F11=A11,1,FALSE) -> 1 | H11: REFLEXO SOBRE ESCALA | I11: =IF(H11=B11,1,FALSE) -> 1
A12: 0011 | B12: Desc. INSS 13º Salario | C12: DESCONTO | D12: VALOR | E12: 9201-Contribuicao Previdenciaria | F12: 0011 | G12: =IF(F12=A12,1,FALSE) -> 1 | H12: DESC. INSS 13º SALARIO | I12: =IF(H12=B12,1,FALSE) -> 1
A13: 0012 | B13: Desc. Contribuicao Sindical Compulsoria | C13: DESCONTO | D13: DIA | E13: 9230-Contribuicao sindical laboral | F13: 0012 | G13: =IF(F13=A13,1,FALSE) -> 1 | H13: DESC. CONTRIBUICAO SINDICAL COMPULSORIA | I13: =IF(H13=B13,1,FALSE) -> 1
... A24: 0023 | B24: Adic de Periculosidade | C24: PROVENTO | D24: VALOR | E24: 1203-Adicional de periculosidade | F24: 0023 | G24: =IF(F24=A24,1,FALSE) -> 1 | H24: ADIC DE PERICULOSIDADE | I24: =IF(H24=B24,1,FALSE) -> 1
A25: 0024 | B25: Ferias Indenizadas Rescisao | C25: PROVENTO | D25: VALOR | E25: 6007-Ferias vencidas na rescisao | F25: 0024 | G25: =IF(F25=A25,1,FALSE) -> 1 | H25: FERIAS VENCIDAS | I25: 1
A26: 0025 | B26: Ferias Proporcionais | C26: PROVENTO | D26: VALOR | E26: 6006-Ferias proporcionais | F26: 0025 | G26: =IF(F26=A26,1,FALSE) -> 1 | H26: FERIAS PROPORCIONAIS | I26: =IF(H26=B26,1,FALSE) -> 1
A27: 0026 | B27: GRRF - FGTS Quitacao | C27: BASE | D27: VALOR | E27: 9989-Outros valores informativos | F27: 0026 | G27: =IF(F27=A27,1,FALSE) -> 1 | H27: GRRF - FGTS QUITACAO | I27: =IF(H27=B27,1,FALSE) -> 1
A28: 0027 | B28: Base - FGTS Mes anterior | C28: BASE | D28: VALOR | E28: 9989-Outros valores informativos | F28: 0027 | G28: =IF(F28=A28,1,FALSE) -> 1 | H28: BASE - FGTS MES ANTERIOR | I28: =IF(H28=B28,1,FALSE) -> 1
A29: 0028 | B29: GRRF - FGTS Artigo 22 | C29: BASE | D29: VALOR | E29: 9989-Outros valores informativos | F29: 0028 | G29: =IF(F29=A29,1,FALSE) -> 1 | H29: GRRF - FGTS ARTIGO 22 | I29: =IF(H29=B29,1,FALSE) -> 1
A30: 0029 | B30: Base - INSS Outro Emprego | C30: BASE | D30: VALOR | E30: 9989-Outros valores informativos | F30: 0029 | G30: =IF(F30=A30,1,FALSE) -> 1 | H30: BASE - INSS OUTRO EMPREGO | I30: =IF(H30=B30,1,FALSE) -> 1
A31: 0030 | B31: Desc. IRRF Ferias | C31: DESCONTO | D31: VALOR | E31: 9203-Imposto de renda retido na fonte | F31: 0030 | G31: =IF(F31=A31,1,FALSE) -> 1 | H31: DESC. IRRF FERIAS | I31: =IF(H31=B31,1,FALSE) -> 1
A32: 0031 | B32: GRRF - FGTS 13º rescisao | C32: BASE | D32: VALOR | E32: 9989-Outros valores informativos | F32: 0031 | G32: =IF(F32=A32,1,FALSE) -> 1 | H32: GRRF - FGTS 13º RESCISAO | I32: =IF(H32=B32,1,FALSE) -> 1
A33: 0032 | B33: Total Entregue Vale Transporte | C33: BASE | D33: VALOR | E33: 9989-Outros valores informativos | F33: 0032 | G33: =IF(F33=A33,1,FALSE) -> 1 | H33: TOTAL ENTREGUE VALE TRANSPORTE | I33: =IF(H33=B33,1,FALSE) -> 1
A34: 0033 | B34: Base - Saldo FGTS no Banco | C34: BASE | D34: VALOR | E34: 9989-Outros valores informativos | F34: 0033 | G34: =IF(F34=A34,1,FALSE) -> 1 | H34: BASE - SALDO FGTS NO BANCO | I34: =IF(H34=B34,1,FALSE) -> 1
A35: 0034 | B35: ( + ) Adiantamento Salarial (P) | C35: PROVENTO | D35: VALOR | E35: 5501-Adiantamento de salario | F35: 0034 | G35: =IF(F35=A35,1,FALSE) -> 1 | H35: ( + ) ADIANTAMENTO SALARIAL (P) | I35: =IF(H35=B35,1,FALSE) -> 1
A36: 0035 | B36: Desc. Adiantamento 13º salario | C36: DESCONTO | D36: VALOR | E36: 9214-13° salario - desconto de adiantamento | F36: 0035 | G36: =IF(F36=A36,1,FALSE) -> 1 | H36: DESC. ADIANTAMENTO 13º SALARIO | I36: =IF(H36=B36,1,FALSE) -> 1
A37: 0036 | B37: Desc. de uma parcela | C37: DESCONTO | D37: VALOR | E37: 9254-Emprestimos consignados - desconto | F37: 0036 | G37: =IF(F37=A37,1,FALSE) -> 1 | H37: DESC. DE UMA PARCELA | I37: =IF(H37=B37,1,FALSE) -> 1
A38: 0037 | B38: Dif. Salarial | C38: PROVENTO | D38: VALOR | E38: 1099-Outras verbas salariais | F38: 0037 | G38: =IF(F38=A38,1,FALSE) -> 1 | H38: DIF. SALARIAL | I38: =IF(H38=B38,1,FALSE) -> 1
A39: 0038 | B39: Dias de Ferias (Recibo) | C39: PROVENTO | D39: VALOR | E39: 1016-Ferias | F39: 0038 | G39: =IF(F39=A39,1,FALSE) -> 1 | H39: REMUNERACAO DE FERIAS (RECIBO) | I39: 1
A40: 0039 | B40: Abono de Ferias | C40: PROVENTO | D40: VALOR | E40: 1023-Ferias - abono pecuniario | F40: 0039 | G40: =IF(F40=A40,1,FALSE) -> 1 | H40: ABONO DE FERIAS | I40: =IF(H40=B40,1,FALSE) -> 1
A41: 0040 | B41: 1/3 de Ferias (Recibo) | C41: PROVENTO | D41: VALOR | E41: 1016-Ferias | F41: 0040 | G41: =IF(F41=A41,1,FALSE) -> 1 | H41: 1/3 DE FERIAS (RECIBO) | I41: =IF(H41=B41,1,FALSE) -> 1
A42: 0041 | B42: Ferias no Mes | C42: PROVENTO | D42: VALOR | E42: 1016-Ferias | F42: 0041 | G42: =IF(F42=A42,1,FALSE) -> 1 | H42: FERIAS NO MES | I42: =IF(H42=B42,1,FALSE) -> 1
A43: 0042 | B43: Ferias no Proximo Mes | C43: PROVENTO | D43: VALOR | E43: 1016-Ferias | F43: 0042 | G43: =IF(F43=A43,1,FALSE) -> 1 | H43: FERIAS NO PROXIMO MES | I43: =IF(H43=B43,1,FALSE) -> 1
A44: 0043 | B44: Desc. Adto Liquido de Ferias | C44: DESCONTO | D44: VALOR | E44: 9200-Desconto de Adiantamentos | F44: 0043 | G44: =IF(F44=A44,1,FALSE) -> 1 | H44: DESC. ADTO LIQUIDO DE FERIAS | I44: =IF(H44=B44,1,FALSE) -> 1
A45: 0044 | B45: Base - Ferias Pagas no Mes Anterior | C45: BASE | D45: VALOR | E45: 1016-Ferias | F45: 0044 | G45: =IF(F45=A45,1,FALSE) -> 1 | H45: BASE - FERIAS PAGAS NO MES ANTERIOR | I45: =IF(H45=B45,1,FALSE) -> 1
A46: 0045 | B46: Dif. Ferias Pagas no Mes | C46: PROVENTO | D46: VALOR | E46: 1016-Ferias | F46: 0045 | G46: =IF(F46=A46,1,FALSE) -> 1 | H46: DIF. FERIAS PAGAS NO MES | I46: =IF(H46=B46,1,FALSE) -> 1
A47: 0046 | B47: Honorarios a Conselheiros | C47: PROVENTO | D47: VALOR | E47: 3509-Honorarios a conselheiros | F47: 0046 | G47: =IF(F47=A47,1,FALSE) -> 1 | H47: HONORARIOS A CONSELHEIROS | I47: =IF(H47=B47,1,FALSE) -> 1
A48: 0047 | B48: Desc. 2a via PASSCARD | C48: DESCONTO | D48: VALOR | E48: 9299-Outros descontos | F48: 0047 | G48: =IF(F48=A48,1,FALSE) -> 1 | H48: DESC. 2A VIA PASSCARD | I48: =IF(H48=B48,1,FALSE) -> 1
A49: 0048 | B49: 13º Salario Rescisao | C49: PROVENTO | D49: VALOR | E49: 6002-13º salario - proporcional na rescisao | F49: 0048 | G49: =IF(F49=A49,1,FALSE) -> 1 | H49: 13º SALARIO RESCISAO | I49: =IF(H49=B49,1,FALSE) -> 1
A50: 0049 | B50: Desc. IRRF s/13º Salario | C50: DESCONTO | D50: VALOR | E50: 9203-Imposto de renda retido na fonte | F50: 0049 | G50: =IF(F50=A50,1,FALSE) -> 1 | H50: DESC. IRRF S/13º SALARIO | I50: =IF(H50=B50,1,FALSE) -> 1
...

Sheet ZDEPARA_EVENTOS_original
A1: EMPRESA_DE | B1: CODIGO_DE | C1: NOME_DE | D1: TIPO_EVENTO | E1: COLIGADA_PARA | F1: CODIGO_PARA | G1: NOME_RM | H1: CODIGO_PARA_FICHA_MES1 | I1: NOME_RM_1 | J1: CODIGO_PARA_FICHA_MES2 | K1: NOME_RM_2 | L1: CODIGO_PARA_VERBAS_FERIAS | M1: NOME_RM_3
A2: 0004 | B2: 0967 | C2: # 1ª via cartão hapvida | D2: D-DESCONTO | E2: 1 | F2: CRIAR EVENTO | G2: =IFERROR(VLOOKUP(F2, DADOS_RM_EVENTOS_original!A:B, 2, FALSE), "Código não encontrado/Não digitado") -> Código não encontrado/Não digitado | I2: =IFERROR(VLOOKUP(H2, DADOS_RM_EVENTOS_original!C:D, 2, FALSE), "Código não encontrado/Não digitado") -> Código não encontrado/Não digitado | K2: =IFERROR(VLOOKUP(J2, DADOS_RM_EVENTOS_original!E:J, 2, FALSE), "Código não encontrado/Não digitado") -> Código não encontrado/Não digitado | M2: =IFERROR(VLOOKUP(L2, DADOS_RM_EVENTOS_original!K:L, 2, FALSE), "Código não encontrado/Não digitado") -> Código não encontrado/Não digitado
A3: 0004 | B3: 0608 | C3: # adiantamento base de cálculo | D3: B-BASE | E3: 1 | F3: NÃO IMPORTAR | G3: =IFERROR(VLOOKUP(F3, DADOS_RM_EVENTOS_original!A:B, 2, FALSE), "Código não encontrado/Não digitado") -> Código não encontrado/Não digitado | I3: =IFERROR(VLOOKUP(H3, DADOS_RM_EVENTOS_original!C:D, 2, FALSE), "Código não encontrado/Não digitado") -> Código não encontrado/Não digitado | K3: =IFERROR(VLOOKUP(J3, DADOS_RM_EVENTOS_original!E:J, 2, FALSE), "Código não encontrado/Não digitado") -> Código não encontrado/Não digitado | M3: =IFERROR(VLOOKUP(L3, DADOS_RM_EVENTOS_original!K:L, 2, FALSE), "Código não encontrado/Não digitado") -> Código não encontrado/Não digitado
A4: 0015 | B4: 0151 | C4: # adiantamento de 13º salário (férias) | D4: P-PROVENTO | E4: 2 | F4: 0444 | G4: =IFERROR(VLOOKUP(F4, DADOS_RM_EVENTOS_original!A:B, 2, FALSE), "Código não encontrado/Não digitado") -> Antecipacao Primeira Parcela 13º nas Fer | I4: =IFERROR(VLOOKUP(H4, DADOS_RM_EVENTOS_original!C:D, 2, FALSE), "Código não encontrado/Não digitado") -> Código não encontrado/Não digitado | K4: =IFERROR(VLOOKUP(J4, DADOS_RM_EVENTOS_original!E:J, 2, FALSE), "Código não encontrado/Não digitado") -> Código não encontrado/Não digitado | M4: =IFERROR(VLOOKUP(L4, DADOS_RM_EVENTOS_original!K:L, 2, FALSE), "Código não encontrado/Não digitado") -> Código não encontrado/Não digitado
A5: 0004 | B5: 0345 | C5: # adiantamento extra | D5: D-DESCONTO | E5: 1 | F5: 0019 | G5: =IFERROR(VLOOKUP(F5, DADOS_RM_EVENTOS_original!A:B, 2, FALSE), "Código não encontrado/Não digitado") -> ( - ) Desc. Adiantamento Salarial | I5: =IFERROR(VLOOKUP(H5, DADOS_RM_EVENTOS_original!C:D, 2, FALSE), "Código não encontrado/Não digitado") -> Código não encontrado/Não digitado | K5: =IFERROR(VLOOKUP(J5, DADOS_RM_EVENTOS_original!E:J, 2, FALSE), "Código não encontrado/Não digitado") -> Código não encontrado/Não digitado | M5: =IFERROR(VLOOKUP(L5, DADOS_RM_EVENTOS_original!K:L, 2, FALSE), "Código não encontrado/Não digitado") -> Código não encontrado/Não digitado
A6: 0004 | B6: 0342 | C6: # almoco | D6: D-DESCONTO | E6: 1 | F6: 0092 | G6: =IFERROR(VLOOKUP(F6, DADOS_RM_EVENTOS_original!A:B, 2, FALSE), "Código não encontrado/Não digitado") -> Desc. Vale Alimentacao | I6: =IFERROR(VLOOKUP(H6, DADOS_RM_EVENTOS_original!C:D, 2, FALSE), "Código não encontrado/Não digitado") -> Código não encontrado/Não digitado | K6: =IFERROR(VLOOKUP(J6, DADOS_RM_EVENTOS_original!E:J, 2, FALSE), "Código não encontrado/Não digitado") -> Código não encontrado/Não digitado | M6: =IFERROR(VLOOKUP(L6, DADOS_RM_EVENTOS_original!K:L, 2, FALSE), "Código não encontrado/Não digitado") -> Código não encontrado/Não digitado
A7: 0004 | B7: 0391 | C7: # arredondamento (desconto) | D7: D-DESCONTO | E7: 1 | F7: 0275 | G7: =IFERROR(VLOOKUP(F7, DADOS_RM_EVENTOS_original!A:B, 2, FALSE), "Código não encontrado/Não digitado") -> Desc. Arred. Liquido Insufuciente | I7: =IFERROR(VLOOKUP(H7, DADOS_RM_EVENTOS_original!C:D, 2, FALSE), "Código não encontrado/Não digitado") -> Código não encontrado/Não digitado | K7: =IFERROR(VLOOKUP(J7, DADOS_RM_EVENTOS_original!E:J, 2, FALSE), "Código não encontrado/Não digitado") -> Código não encontrado/Não digitado | M7: =IFERROR(VLOOKUP(L7, DADOS_RM_EVENTOS_original!K:L, 2, FALSE), "Código não encontrado/Não digitado") -> Código não encontrado/Não digitado
A8: 0004 | B8: 0091 | C8: # arredondamento (provento) | D8: P-PROVENTO | E8: 1 | F8: 0817 | G8: =IFERROR(VLOOKUP(F8, DADOS_RM_EVENTOS_original!A:B, 2, FALSE), "Código não encontrado/Não digitado") -> Arredondamento Liquido Insuficiente | I8: =IFERROR(VLOOKUP(H8, DADOS_RM_EVENTOS_original!C:D, 2, FALSE), "Código não encontrado/Não digitado") -> Código não encontrado/Não digitado | K8: =IFERROR(VLOOKUP(J8, DADOS_RM_EVENTOS_original!E:J, 2, FALSE), "Código não encontrado/Não digitado") -> Código não encontrado/Não digitado | M8: =IFERROR(VLOOKUP(L8, DADOS_RM_EVENTOS_original!K:L, 2, FALSE), "Código não encontrado/Não digitado") -> Código não encontrado/Não digitado
A9: 0004 | B9: 0392 | C9: # arredondamento compensação (desconto) | D9: D-DESCONTO | E9: 1 | F9: 0275 | G9: =IFERROR(VLOOKUP(F9, DADOS_RM_EVENTOS_original!A:B, 2, FALSE), "Código não encontrado/Não digitado") -> Desc. Arred. Liquido Insufuciente | I9: =IFERROR(VLOOKUP(H9, DADOS_RM_EVENTOS_original!C:D, 2, FALSE), "Código não encontrado/Não digitado") -> Código não encontrado/Não digitado | K9: =IFERROR(VLOOKUP(J9, DADOS_RM_EVENTOS_original!E:J, 2, FALSE), "Código não encontrado/Não digitado") -> Código não encontrado/Não digitado | M9: =IFERROR(VLOOKUP(L9, DADOS_RM_EVENTOS_original!K:L, 2, FALSE), "Código não encontrado/Não digitado") -> Código não encontrado/Não digitado
A10: 0004 | B10: 0170 | C10: # complemento de 13º salário | D10: P-PROVENTO | E10: 1 | F10: 0839 | G10: =IFERROR(VLOOKUP(F10, DADOS_RM_EVENTOS_original!A:B, 2, FALSE), "Código não encontrado/Não digitado") -> Dif. 13º Salario (Janeiro) | I10: =IFERROR(VLOOKUP(H10, DADOS_RM_EVENTOS_original!C:D, 2, FALSE), "Código não encontrado/Não digitado") -> Código não encontrado/Não digitado | K10: =IFERROR(VLOOKUP(J10, DADOS_RM_EVENTOS_original!E:J, 2, FALSE), "Código não encontrado/Não digitado") -> Código não encontrado/Não digitado | M10: =IFERROR(VLOOKUP(L10, DADOS_RM_EVENTOS_original!K:L, 2, FALSE), "Código não encontrado/Não digitado") -> Código não encontrado/Não digitado
A11: 0004 | B11: 0338 | C11: # contribuicao sindical mensal | D11: D-DESCONTO | E11: 1 | F11: 0201 | G11: =IFERROR(VLOOKUP(F11, DADOS_RM_EVENTOS_original!A:B, 2, FALSE), "Código não encontrado/Não digitado") -> Desc. Mensalidade Sindical | I11: =IFERROR(VLOOKUP(H11, DADOS_RM_EVENTOS_original!C:D, 2, FALSE), "Código não encontrado/Não digitado") -> Código não encontrado/Não digitado | K11: =IFERROR(VLOOKUP(J11, DADOS_RM_EVENTOS_original!E:J, 2, FALSE), "Código não encontrado/Não digitado") -> Código não encontrado/Não digitado | M11: =IFERROR(VLOOKUP(L11, DADOS_RM_EVENTOS_original!K:L, 2, FALSE), "Código não encontrado/Não digitado") -> Código não encontrado/Não digitado
A12: 0004 | B12: 0221 | C12: # desc cartao vale transporte eletronico | D12: D-DESCONTO | E12: 1 | F12: 0047 | G12: =IFERROR(VLOOKUP(F12, DADOS_RM_EVENTOS_original!A:B, 2, FALSE), "Código não encontrado/Não digitado") -> Desc. 2a via PASSCARD | I12: =IFERROR(VLOOKUP(H12, DADOS_RM_EVENTOS_original!C:D, 2, FALSE), "Código não encontrado/Não digitado") -> Código não encontrado/Não digitado | K12: =IFERROR(VLOOKUP(J12, DADOS_RM_EVENTOS_original!E:J, 2, FALSE), "Código não encontrado/Não digitado") -> Código não encontrado/Não digitado | M12: =IFERROR(VLOOKUP(L12, DADOS_RM_EVENTOS_original!K:L, 2, FALSE), "Código não encontrado/Não digitado") -> Código não encontrado/Não digitado
A13: 0004 | B13: 0139 | C13: # devol.contribuicao sindical | D13: P-PROVENTO | E13: 1 | F13: 0324 | G13: =IFERROR(VLOOKUP(F13, DADOS_RM_EVENTOS_original!A:B, 2, FALSE), "Código não encontrado/Não digitado") -> Reembolso de Contribuicao Sindical | I13: =IFERROR(VLOOKUP(H13, DADOS_RM_EVENTOS_original!C:D, 2, FALSE), "Código não encontrado/Não digitado") -> Código não encontrado/Não digitado | K13: =IFERROR(VLOOKUP(J13, DADOS_RM_EVENTOS_original!E:J, 2, FALSE), "Código não encontrado/Não digitado") -> Código não encontrado/Não digitado | M13: =IFERROR(VLOOKUP(L13, DADOS_RM_EVENTOS_original!K:L, 2, FALSE), "Código não encontrado/Não digitado") -> Código não encontrado/Não digitado
... A56: 0012 | B56: 0967 | C56: 1/3 de Abono Pecuniário | D56: P-PROVENTO | E56: 5 | F56: 0056 | G56: =IFERROR(VLOOKUP(F56, DADOS_RM_EVENTOS_original!A:B, 2, FALSE), "Código não encontrado/Não digitado") -> 1/3 Abono de Ferias | I56: =IFERROR(VLOOKUP(H56, DADOS_RM_EVENTOS_original!C:D, 2, FALSE), "Código não encontrado/Não digitado") -> Código não encontrado/Não digitado | K56: =IFERROR(VLOOKUP(J56, DADOS_RM_EVENTOS_original!E:J, 2, FALSE), "Código não encontrado/Não digitado") -> Código não encontrado/Não digitado | M56: =IFERROR(VLOOKUP(L56, DADOS_RM_EVENTOS_original!K:L, 2, FALSE), "Código não encontrado/Não digitado") -> Código não encontrado/Não digitado
A57: 0004 | B57: 0111 | C57: 1/3 DE FÉRIAS | D57: P-PROVENTO | E57: 1 | F57: 0076 | G57: =IFERROR(VLOOKUP(F57, DADOS_RM_EVENTOS_original!A:B, 2, FALSE), "Código não encontrado/Não digitado") -> 1/3 Ferias no Mes | H57: 0076 | I57: =IFERROR(VLOOKUP(H57, DADOS_RM_EVENTOS_original!A:D, 2, FALSE), "Código não encontrado/Não digitado") -> 1/3 Ferias no Mes | J57: 0077 | K57: =IFERROR(VLOOKUP(J57, DADOS_RM_EVENTOS_original!A:J, 2, FALSE), "Código não encontrado/Não digitado") -> 1/3 Ferias no Proximo Mes | L57: 0040 | M57: =IFERROR(VLOOKUP(L57, DADOS_RM_EVENTOS_original!A:L, 2, FALSE), "Código não encontrado/Não digitado") -> 1/3 de Ferias (Recibo)
A58: 0015 | B58: 0111 | C58: 1/3 DE FÉRIAS | D58: P-PROVENTO | E58: 2 | F58: 0076 | G58: =IFERROR(VLOOKUP(F58, DADOS_RM_EVENTOS_original!A:B, 2, FALSE), "Código não encontrado/Não digitado") -> 1/3 Ferias no Mes | H58: 0076 | I58: =IFERROR(VLOOKUP(H58, DADOS_RM_EVENTOS_original!A:D, 2, FALSE), "Código não encontrado/Não digitado") -> 1/3 Ferias no Mes | J58: 0077 | K58: =IFERROR(VLOOKUP(J58, DADOS_RM_EVENTOS_original!A:J, 2, FALSE), "Código não encontrado/Não digitado") -> 1/3 Ferias no Proximo Mes | L58: 0040 | M58: =IFERROR(VLOOKUP(L58, DADOS_RM_EVENTOS_original!A:L, 2, FALSE), "Código não encontrado/Não digitado") -> 1/3 de Ferias (Recibo)
A59: 0017 | B59: 0111 | C59: 1/3 de Férias | D59: P-PROVENTO | E59: 3 | F59: 0076 | G59: =IFERROR(VLOOKUP(F59, DADOS_RM_EVENTOS_original!A:B, 2, FALSE), "Código não encontrado/Não digitado") -> 1/3 Ferias no Mes | H59: 0076 | I59: =IFERROR(VLOOKUP(H59, DADOS_RM_EVENTOS_original!A:D, 2, FALSE), "Código não encontrado/Não digitado") -> 1/3 Ferias no Mes | J59: 0077 | K59: =IFERROR(VLOOKUP(J59, DADOS_RM_EVENTOS_original!A:J, 2, FALSE), "Código não encontrado/Não digitado") -> 1/3 Ferias no Proximo Mes | L59: 0040 | M59: =IFERROR(VLOOKUP(L59, DADOS_RM_EVENTOS_original!A:L, 2, FALSE), "Código não encontrado/Não digitado") -> 1/3 de Ferias (Recibo)
A60: 0005 | B60: 0111 | C60: 1/3 de Férias | D60: P-PROVENTO | E60: 4 | F60: 0076 | G60: =IFERROR(VLOOKUP(F60, DADOS_RM_EVENTOS_original!A:B, 2, FALSE), "Código não encontrado/Não digitado") -> 1/3 Ferias no Mes | H60: 0076 | I60: =IFERROR(VLOOKUP(H60, DADOS_RM_EVENTOS_original!A:D, 2, FALSE), "Código não encontrado/Não digitado") -> 1/3 Ferias no Mes | J60: 0077 | K60: =IFERROR(VLOOKUP(J60, DADOS_RM_EVENTOS_original!A:J, 2, FALSE), "Código não encontrado/Não digitado") -> 1/3 Ferias no Proximo Mes | L60: 0040 | M60: =IFERROR(VLOOKUP(L60, DADOS_RM_EVENTOS_original!A:L, 2, FALSE), "Código não encontrado/Não digitado") -> 1/3 de Ferias (Recibo)
A61: 0012 | B61: 0111 | C61: 1/3 de Férias | D61: P-PROVENTO | E61: 5 | F61: 0076 | G61: =IFERROR(VLOOKUP(F61, DADOS_RM_EVENTOS_original!A:B, 2, FALSE), "Código não encontrado/Não digitado") -> 1/3 Ferias no Mes | H61: 0076 | I61: =IFERROR(VLOOKUP(H61, DADOS_RM_EVENTOS_original!A:D, 2, FALSE), "Código não encontrado/Não digitado") -> 1/3 Ferias no Mes | J61: 0077 | K61: =IFERROR(VLOOKUP(J61, DADOS_RM_EVENTOS_original!A:J, 2, FALSE), "Código não encontrado/Não digitado") -> 1/3 Ferias no Proximo Mes | L61: 0040 | M61: =IFERROR(VLOOKUP(L61, DADOS_RM_EVENTOS_original!A:L, 2, FALSE), "Código não encontrado/Não digitado") -> 1/3 de Ferias (Recibo)
A62: 0022 | B62: 0111 | C62: 1/3 de Férias | D62: P-PROVENTO | E62: 6 | F62: 0076 | G62: =IFERROR(VLOOKUP(F62, DADOS_RM_EVENTOS_original!A:B, 2, FALSE), "Código não encontrado/Não digitado") -> 1/3 Ferias no Mes | H62: 0076 | I62: =IFERROR(VLOOKUP(H62, DADOS_RM_EVENTOS_original!A:D, 2, FALSE), "Código não encontrado/Não digitado") -> 1/3 Ferias no Mes | J62: 0077 | K62: =IFERROR(VLOOKUP(J62, DADOS_RM_EVENTOS_original!A:J, 2, FALSE), "Código não encontrado/Não digitado") -> 1/3 Ferias no Proximo Mes | L62: 0040 | M62: =IFERROR(VLOOKUP(L62, DADOS_RM_EVENTOS_original!A:L, 2, FALSE), "Código não encontrado/Não digitado") -> 1/3 de Ferias (Recibo)
A63: 0004 | B63: 0207 | C63: 1/3 DE FÉRIAS (RESCISÃO) | D63: P-PROVENTO | E63: 1 | F63: 0063 | G63: =IFERROR(VLOOKUP(F63, DADOS_RM_EVENTOS_original!A:B, 2, FALSE), "Código não encontrado/Não digitado") -> 1/3 Ferias Rescisao | I63: =IFERROR(VLOOKUP(H63, DADOS_RM_EVENTOS_original!C:D, 2, FALSE), "Código não encontrado/Não digitado") -> Código não encontrado/Não digitado | K63: =IFERROR(VLOOKUP(J63, DADOS_RM_EVENTOS_original!E:J, 2, FALSE), "Código não encontrado/Não digitado") -> Código não encontrado/Não digitado | M63: =IFERROR(VLOOKUP(L63, DADOS_RM_EVENTOS_original!K:L, 2, FALSE), "Código não encontrado/Não digitado") -> Código não encontrado/Não digitado
A64: 0005 | B64: 0207 | C64: 1/3 de Férias (Rescisão) | D64: P-PROVENTO | E64: 4 | F64: 0063 | G64: =IFERROR(VLOOKUP(F64, DADOS_RM_EVENTOS_original!A:B, 2, FALSE), "Código não encontrado/Não digitado") -> 1/3 Ferias Rescisao | I64: =IFERROR(VLOOKUP(H64, DADOS_RM_EVENTOS_original!C:D, 2, FALSE), "Código não encontrado/Não digitado") -> Código não encontrado/Não digitado | K64: =IFERROR(VLOOKUP(J64, DADOS_RM_EVENTOS_original!E:J, 2, FALSE), "Código não encontrado/Não digitado") -> Código não encontrado/Não digitado | M64: =IFERROR(VLOOKUP(L64, DADOS_RM_EVENTOS_original!K:L, 2, FALSE), "Código não encontrado/Não digitado") -> Código não encontrado/Não digitado
A65: 0012 | B65: 0207 | C65: 1/3 de Férias (Rescisão) | D65: P-PROVENTO | E65: 5 | F65: 0063 | G65: =IFERROR(VLOOKUP(F65, DADOS_RM_EVENTOS_original!A:B, 2, FALSE), "Código não encontrado/Não digitado") -> 1/3 Ferias Rescisao | I65: =IFERROR(VLOOKUP(H65, DADOS_RM_EVENTOS_original!C:D, 2, FALSE), "Código não encontrado/Não digitado") -> Código não encontrado/Não digitado | K65: =IFERROR(VLOOKUP(J65, DADOS_RM_EVENTOS_original!E:J, 2, FALSE), "Código não encontrado/Não digitado") -> Código não encontrado/Não digitado | M65: =IFERROR(VLOOKUP(L65, DADOS_RM_EVENTOS_original!K:L, 2, FALSE), "Código não encontrado/Não digitado") -> Código não encontrado/Não digitado
A66: 0004 | B66: 0987 | C66: 1/3 de Férias Indenizadas | D66: P-PROVENTO | E66: 1 | F66: 0063 | G66: =IFERROR(VLOOKUP(F66, DADOS_RM_EVENTOS_original!A:B, 2, FALSE), "Código não encontrado/Não digitado") -> 1/3 Ferias Rescisao | I66: =IFERROR(VLOOKUP(H66, DADOS_RM_EVENTOS_original!C:D, 2, FALSE), "Código não encontrado/Não digitado") -> Código não encontrado/Não digitado | K66: =IFERROR(VLOOKUP(J66, DADOS_RM_EVENTOS_original!E:J, 2, FALSE), "Código não encontrado/Não digitado") -> Código não encontrado/Não digitado | M66: =IFERROR(VLOOKUP(L66, DADOS_RM_EVENTOS_original!K:L, 2, FALSE), "Código não encontrado/Não digitado") -> Código não encontrado/Não digitado
A67: 0017 | B67: 0968 | C67: 1/3 de Férias Proporcionais | D67: P-PROVENTO | E67: 3 | F67: 0063 | G67: =IFERROR(VLOOKUP(F67, DADOS_RM_EVENTOS_original!A:B, 2, FALSE), "Código não encontrado/Não digitado") -> 1/3 Ferias Rescisao | I67: =IFERROR(VLOOKUP(H67, DADOS_RM_EVENTOS_original!C:D, 2, FALSE), "Código não encontrado/Não digitado") -> Código não encontrado/Não digitado | K67: =IFERROR(VLOOKUP(J67, DADOS_RM_EVENTOS_original!E:J, 2, FALSE), "Código não encontrado/Não digitado") -> Código não encontrado/Não digitado | M67: =IFERROR(VLOOKUP(L67, DADOS_RM_EVENTOS_original!K:L, 2, FALSE), "Código não encontrado/Não digitado") -> Código não encontrado/Não digitado
A68: 0005 | B68: 0960 | C68: 1/3 de Férias Proporcionais | D68: P-PROVENTO | E68: 4 | F68: 0063 | G68: =IFERROR(VLOOKUP(F68, DADOS_RM_EVENTOS_original!A:B, 2, FALSE), "Código não encontrado/Não digitado") -> 1/3 Ferias Rescisao | I68: =IFERROR(VLOOKUP(H68, DADOS_RM_EVENTOS_original!C:D, 2, FALSE), "Código não encontrado/Não digitado") -> Código não encontrado/Não digitado | K68: =IFERROR(VLOOKUP(J68, DADOS_RM_EVENTOS_original!E:J, 2, FALSE), "Código não encontrado/Não digitado") -> Código não encontrado/Não digitado | M68: =IFERROR(VLOOKUP(L68, DADOS_RM_EVENTOS_original!K:L, 2, FALSE), "Código não encontrado/Não digitado") -> Código não encontrado/Não digitado
A69: 0012 | B69: 0959 | C69: 1/3 de Férias Proporcionais | D69: P-PROVENTO | E69: 5 | F69: 0063 | G69: =IFERROR(VLOOKUP(F69, DADOS_RM_EVENTOS_original!A:B, 2, FALSE), "Código não encontrado/Não digitado") -> 1/3 Ferias Rescisao | I69: =IFERROR(VLOOKUP(H69, DADOS_RM_EVENTOS_original!C:D, 2, FALSE), "Código não encontrado/Não digitado") -> Código não encontrado/Não digitado | K69: =IFERROR(VLOOKUP(J69, DADOS_RM_EVENTOS_original!E:J, 2, FALSE), "Código não encontrado/Não digitado") -> Código não encontrado/Não digitado | M69: =IFERROR(VLOOKUP(L69, DADOS_RM_EVENTOS_original!K:L, 2, FALSE), "Código não encontrado/Não digitado") -> Código não encontrado/Não digitado
A70: 0022 | B70: 0212 | C70: 1/3 de Férias Proporcionais | D70: P-PROVENTO | E70: 6 | F70: 0063 | G70: =IFERROR(VLOOKUP(F70, DADOS_RM_EVENTOS_original!A:B, 2, FALSE), "Código não encontrado/Não digitado") -> 1/3 Ferias Rescisao | I70: =IFERROR(VLOOKUP(H70, DADOS_RM_EVENTOS_original!C:D, 2, FALSE), "Código não encontrado/Não digitado") -> Código não encontrado/Não digitado | K70: =IFERROR(VLOOKUP(J70, DADOS_RM_EVENTOS_original!E:J, 2, FALSE), "Código não encontrado/Não digitado") -> Código não encontrado/Não digitado | M70: =IFERROR(VLOOKUP(L70, DADOS_RM_EVENTOS_original!K:L, 2, FALSE), "Código não encontrado/Não digitado") -> Código não encontrado/Não digitado
A71: 0004 | B71: 0973 | C71: 1/3 de Férias Proporcionais 1 | D71: P-PROVENTO | E71: 1 | F71: 0063 | G71: =IFERROR(VLOOKUP(F71, DADOS_RM_EVENTOS_original!A:B, 2, FALSE), "Código não encontrado/Não digitado") -> 1/3 Ferias Rescisao | I71: =IFERROR(VLOOKUP(H71, DADOS_RM_EVENTOS_original!C:D, 2, FALSE), "Código não encontrado/Não digitado") -> Código não encontrado/Não digitado | K71: =IFERROR(VLOOKUP(J71, DADOS_RM_EVENTOS_original!E:J, 2, FALSE), "Código não encontrado/Não digitado") -> Código não encontrado/Não digitado | M71: =IFERROR(VLOOKUP(L71, DADOS_RM_EVENTOS_original!K:L, 2, FALSE), "Código não encontrado/Não digitado") -> Código não encontrado/Não digitado
A72: 0015 | B72: 0973 | C72: 1/3 de Férias Proporcionais 1 | D72: P-PROVENTO | E72: 2 | F72: 0063 | G72: =IFERROR(VLOOKUP(F72, DADOS_RM_EVENTOS_original!A:B, 2, FALSE), "Código não encontrado/Não digitado") -> 1/3 Ferias Rescisao | I72: =IFERROR(VLOOKUP(H72, DADOS_RM_EVENTOS_original!C:D, 2, FALSE), "Código não encontrado/Não digitado") -> Código não encontrado/Não digitado | K72: =IFERROR(VLOOKUP(J72, DADOS_RM_EVENTOS_original!E:J, 2, FALSE), "Código não encontrado/Não digitado") -> Código não encontrado/Não digitado | M72: =IFERROR(VLOOKUP(L72, DADOS_RM_EVENTOS_original!K:L, 2, FALSE), "Código não encontrado/Não digitado") -> Código não encontrado/Não digitado
A73: 0017 | B73: 0969 | C73: 1/3 de Férias Vencidas | D73: P-PROVENTO | E73: 3 | F73: 0803 | G73: =IFERROR(VLOOKUP(F73, DADOS_RM_EVENTOS_original!A:B, 2, FALSE), "Código não encontrado/Não digitado") -> Adicional 1/3 Ferias Vencidas | I73: =IFERROR(VLOOKUP(H73, DADOS_RM_EVENTOS_original!C:D, 2, FALSE), "Código não encontrado/Não digitado") -> Código não encontrado/Não digitado | K73: =IFERROR(VLOOKUP(J73, DADOS_RM_EVENTOS_original!E:J, 2, FALSE), "Código não encontrado/Não digitado") -> Código não encontrado/Não digitado | M73: =IFERROR(VLOOKUP(L73, DADOS_RM_EVENTOS_original!K:L, 2, FALSE), "Código não encontrado/Não digitado") -> Código não encontrado/Não digitado
A74: 0005 | B74: 0961 | C74: 1/3 de Férias Vencidas | D74: P-PROVENTO | E74: 4 | F74: 0803 | G74: =IFERROR(VLOOKUP(F74, DADOS_RM_EVENTOS_original!A:B, 2, FALSE), "Código não encontrado/Não digitado") -> Adicional 1/3 Ferias Vencidas | I74: =IFERROR(VLOOKUP(H74, DADOS_RM_EVENTOS_original!C:D, 2, FALSE), "Código não encontrado/Não digitado") -> Código não encontrado/Não digitado | K74: =IFERROR(VLOOKUP(J74, DADOS_RM_EVENTOS_original!E:J, 2, FALSE), "Código não encontrado/Não digitado") -> Código não encontrado/Não digitado | M74: =IFERROR(VLOOKUP(L74, DADOS_RM_EVENTOS_original!K:L, 2, FALSE), "Código não encontrado/Não digitado") -> Código não encontrado/Não digitado
... A558: 0012 | B558: 0949 | C558: Refeição Mês Anterior | D558: P-PROVENTO | E558: 5 | F558: 0147 | G558: =IFERROR(VLOOKUP(F558, DADOS_RM_EVENTOS_original!A:B, 2, FALSE), "Código não encontrado/Não digitado") -> Reembolso Desc. Vale Refeicao | I558: =IFERROR(VLOOKUP(H558, DADOS_RM_EVENTOS_original!C:D, 2, FALSE), "Código não encontrado/Não digitado") -> Código não encontrado/Não digitado | K558: =IFERROR(VLOOKUP(J558, DADOS_RM_EVENTOS_original!E:J, 2, FALSE), "Código não encontrado/Não digitado") -> Código não encontrado/Não digitado | M558: =IFERROR(VLOOKUP(L558, DADOS_RM_EVENTOS_original!K:L, 2, FALSE), "Código não encontrado/Não digitado") -> Código não encontrado/Não digitado
A559: 0004 | B559: 0110 | C559: REMUNERAÇÃO DE FÉRIAS | D559: P-PROVENTO | E559: 1 | F559: 0041 | G559: =IFERROR(VLOOKUP(F559, DADOS_RM_EVENTOS_original!A:B, 2, FALSE), "Código não encontrado/Não digitado") -> Ferias no Mes | H559: 0041 | I559: =IFERROR(VLOOKUP(H559, DADOS_RM_EVENTOS_original!A:D, 2, FALSE), "Código não encontrado/Não digitado") -> Ferias no Mes | J559: 0042 | K559: =IFERROR(VLOOKUP(J559, DADOS_RM_EVENTOS_original!A:J, 2, FALSE), "Código não encontrado/Não digitado") -> Ferias no Proximo Mes | L559: 0038 | M559: =IFERROR(VLOOKUP(L559, DADOS_RM_EVENTOS_original!A:L, 2, FALSE), "Código não encontrado/Não digitado") -> Dias de Ferias (Recibo)
A560: 0015 | B560: 0110 | C560: REMUNERAÇÃO DE FÉRIAS | D560: P-PROVENTO | E560: 2 | F560: 0041 | G560: =IFERROR(VLOOKUP(F560, DADOS_RM_EVENTOS_original!A:B, 2, FALSE), "Código não encontrado/Não digitado") -> Ferias no Mes | H560: 0041 | I560: =IFERROR(VLOOKUP(H560, DADOS_RM_EVENTOS_original!A:D, 2, FALSE), "Código não encontrado/Não digitado") -> Ferias no Mes | J560: 0042 | K560: =IFERROR(VLOOKUP(J560, DADOS_RM_EVENTOS_original!A:J, 2, FALSE), "Código não encontrado/Não digitado") -> Ferias no Proximo Mes | L560: 0038 | M560: =IFERROR(VLOOKUP(L560, DADOS_RM_EVENTOS_original!A:L, 2, FALSE), "Código não encontrado/Não digitado") -> Dias de Ferias (Recibo)
A561: 0017 | B561: 0110 | C561: Remuneração de Férias | D561: P-PROVENTO | E561: 3 | F561: 0016 | G561: =IFERROR(VLOOKUP(F561, DADOS_RM_EVENTOS_original!A:B, 2, FALSE), "Código não encontrado/Não digitado") -> Provento ferias | I561: =IFERROR(VLOOKUP(H561, DADOS_RM_EVENTOS_original!C:D, 2, FALSE), "Código não encontrado/Não digitado") -> Código não encontrado/Não digitado | K561: =IFERROR(VLOOKUP(J561, DADOS_RM_EVENTOS_original!E:J, 2, FALSE), "Código não encontrado/Não digitado") -> Código não encontrado/Não digitado | M561: =IFERROR(VLOOKUP(L561, DADOS_RM_EVENTOS_original!K:L, 2, FALSE), "Código não encontrado/Não digitado") -> Código não encontrado/Não digitado
A562: 0005 | B562: 0110 | C562: Remuneração de Férias | D562: P-PROVENTO | E562: 4 | F562: 0041 | G562: =IFERROR(VLOOKUP(F562, DADOS_RM_EVENTOS_original!A:B, 2, FALSE), "Código não encontrado/Não digitado") -> Ferias no Mes | H562: 0041 | I562: =IFERROR(VLOOKUP(H562, DADOS_RM_EVENTOS_original!A:D, 2, FALSE), "Código não encontrado/Não digitado") -> Ferias no Mes | J562: 0042 | K562: =IFERROR(VLOOKUP(J562, DADOS_RM_EVENTOS_original!A:J, 2, FALSE), "Código não encontrado/Não digitado") -> Ferias no Proximo Mes | L562: 0038 | M562: =IFERROR(VLOOKUP(L562, DADOS_RM_EVENTOS_original!A:L, 2, FALSE), "Código não encontrado/Não digitado") -> Dias de Ferias (Recibo)
A563: 0012 | B563: 0110 | C563: Remuneração de Férias | D563: P-PROVENTO | E563: 5 | F563: 0041 | G563: =IFERROR(VLOOKUP(F563, DADOS_RM_EVENTOS_original!A:B, 2, FALSE), "Código não encontrado/Não digitado") -> Ferias no Mes | H563: 0041 | I563: =IFERROR(VLOOKUP(H563, DADOS_RM_EVENTOS_original!A:D, 2, FALSE), "Código não encontrado/Não digitado") -> Ferias no Mes | J563: 0042 | K563: =IFERROR(VLOOKUP(J563, DADOS_RM_EVENTOS_original!A:J, 2, FALSE), "Código não encontrado/Não digitado") -> Ferias no Proximo Mes | L563: 0038 | M563: =IFERROR(VLOOKUP(L563, DADOS_RM_EVENTOS_original!A:L, 2, FALSE), "Código não encontrado/Não digitado") -> Dias de Ferias (Recibo)
A564: 0022 | B564: 0110 | C564: Remuneração de Férias | D564: P-PROVENTO | E564: 6 | F564: 0041 | G564: =IFERROR(VLOOKUP(F564, DADOS_RM_EVENTOS_original!A:B, 2, FALSE), "Código não encontrado/Não digitado") -> Ferias no Mes | H564: 0041 | I564: =IFERROR(VLOOKUP(H564, DADOS_RM_EVENTOS_original!A:D, 2, FALSE), "Código não encontrado/Não digitado") -> Ferias no Mes | J564: 0042 | K564: =IFERROR(VLOOKUP(J564, DADOS_RM_EVENTOS_original!A:J, 2, FALSE), "Código não encontrado/Não digitado") -> Ferias no Proximo Mes | L564: 0038 | M564: =IFERROR(VLOOKUP(L564, DADOS_RM_EVENTOS_original!A:L, 2, FALSE), "Código não encontrado/Não digitado") -> Dias de Ferias (Recibo)
A565: 0004 | B565: 0112 | C565: REMUNERAÇÃO DE FÉRIAS EM DOBRO | D565: P-PROVENTO | E565: 1 | F565: 0240 | G565: =IFERROR(VLOOKUP(F565, DADOS_RM_EVENTOS_original!A:B, 2, FALSE), "Código não encontrado/Não digitado") -> Ferias em Dobro | I565: =IFERROR(VLOOKUP(H565, DADOS_RM_EVENTOS_original!C:D, 2, FALSE), "Código não encontrado/Não digitado") -> Código não encontrado/Não digitado | K565: =IFERROR(VLOOKUP(J565, DADOS_RM_EVENTOS_original!E:J, 2, FALSE), "Código não encontrado/Não digitado") -> Código não encontrado/Não digitado | M565: =IFERROR(VLOOKUP(L565, DADOS_RM_EVENTOS_original!K:L, 2, FALSE), "Código não encontrado/Não digitado") -> Código não encontrado/Não digitado
...

Sheet ZDEPARA_EVENTOS
A1: EMPRESA_DE | B1: CODIGO_DE | C1: NOME_DE | D1: TIPO_EVENTO | E1: COLIGADA_PARA | F1: CODIGO_PARA | G1: NOME_RM | H1: CODIGO_PARA_FICHA_MES1 | I1: NOME_RM_1 | J1: CODIGO_PARA_FICHA_MES2 | K1: NOME_RM_2 | L1: CODIGO_PARA_VERBAS_FERIAS | M1: NOME_RM_3
A2: 0004 | B2: 0967 | C2: # 1ª via cartão hapvida | D2: D-DESCONTO | E2: 1 | F2: CRIAR EVENTO | G2: Código não encontrado/Não digitado | I2: =IFERROR(VLOOKUP(H2, DADOS_RM_EVENTOS_original!C:D, 2, FALSE), "Código não encontrado/Não digitado") -> Código não encontrado/Não digitado | K2: =IFERROR(VLOOKUP(J2, DADOS_RM_EVENTOS_original!E:J, 2, FALSE), "Código não encontrado/Não digitado") -> Código não encontrado/Não digitado | M2: =IFERROR(VLOOKUP(L2, DADOS_RM_EVENTOS_original!K:L, 2, FALSE), "Código não encontrado/Não digitado") -> Código não encontrado/Não digitado
A3: 0004 | B3: 0608 | C3: # adiantamento base de cálculo | D3: B-BASE | E3: 1 | F3: NÃO IMPORTAR | G3: Código não encontrado/Não digitado | I3: =IFERROR(VLOOKUP(H3, DADOS_RM_EVENTOS_original!C:D, 2, FALSE), "Código não encontrado/Não digitado") -> Código não encontrado/Não digitado | K3: =IFERROR(VLOOKUP(J3, DADOS_RM_EVENTOS_original!E:J, 2, FALSE), "Código não encontrado/Não digitado") -> Código não encontrado/Não digitado | M3: =IFERROR(VLOOKUP(L3, DADOS_RM_EVENTOS_original!K:L, 2, FALSE), "Código não encontrado/Não digitado") -> Código não encontrado/Não digitado
A4: 0015 | B4: 0151 | C4: # adiantamento de 13º salário (férias) | D4: P-PROVENTO | E4: 2 | F4: 0444 | G4: Antecipacao Primeira Parcela 13º nas Fer | I4: =IFERROR(VLOOKUP(H4, DADOS_RM_EVENTOS_original!C:D, 2, FALSE), "Código não encontrado/Não digitado") -> Código não encontrado/Não digitado | K4: =IFERROR(VLOOKUP(J4, DADOS_RM_EVENTOS_original!E:J, 2, FALSE), "Código não encontrado/Não digitado") -> Código não encontrado/Não digitado | M4: =IFERROR(VLOOKUP(L4, DADOS_RM_EVENTOS_original!K:L, 2, FALSE), "Código não encontrado/Não digitado") -> Código não encontrado/Não digitado
A5: 0004 | B5: 0345 | C5: # adiantamento extra | D5: D-DESCONTO | E5: 1 | F5: 0019 | G5: ( - ) Desc. Adiantamento Salarial | I5: =IFERROR(VLOOKUP(H5, DADOS_RM_EVENTOS_original!C:D, 2, FALSE), "Código não encontrado/Não digitado") -> Código não encontrado/Não digitado | K5: =IFERROR(VLOOKUP(J5, DADOS_RM_EVENTOS_original!E:J, 2, FALSE), "Código não encontrado/Não digitado") -> Código não encontrado/Não digitado | M5: =IFERROR(VLOOKUP(L5, DADOS_RM_EVENTOS_original!K:L, 2, FALSE), "Código não encontrado/Não digitado") -> Código não encontrado/Não digitado
A6: 0004 | B6: 0342 | C6: # almoco | D6: D-DESCONTO | E6: 1 | F6: 0092 | G6: Desc. Vale Alimentacao | I6: =IFERROR(VLOOKUP(H6, DADOS_RM_EVENTOS_original!C:D, 2, FALSE), "Código não encontrado/Não digitado") -> Código não encontrado/Não digitado | K6: =IFERROR(VLOOKUP(J6, DADOS_RM_EVENTOS_original!E:J, 2, FALSE), "Código não encontrado/Não digitado") -> Código não encontrado/Não digitado | M6: =IFERROR(VLOOKUP(L6, DADOS_RM_EVENTOS_original!K:L, 2, FALSE), "Código não encontrado/Não digitado") -> Código não encontrado/Não digitado
A7: 0004 | B7: 0391 | C7: # arredondamento (desconto) | D7: D-DESCONTO | E7: 1 | F7: 0275 | G7: Desc. Arred. Liquido Insufuciente | I7: =IFERROR(VLOOKUP(H7, DADOS_RM_EVENTOS_original!C:D, 2, FALSE), "Código não encontrado/Não digitado") -> Código não encontrado/Não digitado | K7: =IFERROR(VLOOKUP(J7, DADOS_RM_EVENTOS_original!E:J, 2, FALSE), "Código não encontrado/Não digitado") -> Código não encontrado/Não digitado | M7: =IFERROR(VLOOKUP(L7, DADOS_RM_EVENTOS_original!K:L, 2, FALSE), "Código não encontrado/Não digitado") -> Código não encontrado/Não digitado
A8: 0004 | B8: 0091 | C8: # arredondamento (provento) | D8: P-PROVENTO | E8: 1 | F8: 0817 | G8: Arredondamento Liquido Insuficiente | I8: =IFERROR(VLOOKUP(H8, DADOS_RM_EVENTOS_original!C:D, 2, FALSE), "Código não encontrado/Não digitado") -> Código não encontrado/Não digitado | K8: =IFERROR(VLOOKUP(J8, DADOS_RM_EVENTOS_original!E:J, 2, FALSE), "Código não encontrado/Não digitado") -> Código não encontrado/Não digitado | M8: =IFERROR(VLOOKUP(L8, DADOS_RM_EVENTOS_original!K:L, 2, FALSE), "Código não encontrado/Não digitado") -> Código não encontrado/Não digitado
A9: 0004 | B9: 0392 | C9: # arredondamento compensação (desconto) | D9: D-DESCONTO | E9: 1 | F9: 0275 | G9: Desc. Arred. Liquido Insufuciente | I9: =IFERROR(VLOOKUP(H9, DADOS_RM_EVENTOS_original!C:D, 2, FALSE), "Código não encontrado/Não digitado") -> Código não encontrado/Não digitado | K9: =IFERROR(VLOOKUP(J9, DADOS_RM_EVENTOS_original!E:J, 2, FALSE), "Código não encontrado/Não digitado") -> Código não encontrado/Não digitado | M9: =IFERROR(VLOOKUP(L9, DADOS_RM_EVENTOS_original!K:L, 2, FALSE), "Código não encontrado/Não digitado") -> Código não encontrado/Não digitado
A10: 0004 | B10: 0170 | C10: # complemento de 13º salário | D10: P-PROVENTO | E10: 1 | F10: 0839 | G10: Dif. 13º Salario (Janeiro) | I10: =IFERROR(VLOOKUP(H10, DADOS_RM_EVENTOS_original!C:D, 2, FALSE), "Código não encontrado/Não digitado") -> Código não encontrado/Não digitado | K10: =IFERROR(VLOOKUP(J10, DADOS_RM_EVENTOS_original!E:J, 2, FALSE), "Código não encontrado/Não digitado") -> Código não encontrado/Não digitado | M10: =IFERROR(VLOOKUP(L10, DADOS_RM_EVENTOS_original!K:L, 2, FALSE), "Código não encontrado/Não digitado") -> Código não encontrado/Não digitado
A11: 0004 | B11: 0338 | C11: # contribuicao sindical mensal | D11: D-DESCONTO | E11: 1 | F11: 0201 | G11: Desc. Mensalidade Sindical | I11: =IFERROR(VLOOKUP(H11, DADOS_RM_EVENTOS_original!C:D, 2, FALSE), "Código não encontrado/Não digitado") -> Código não encontrado/Não digitado | K11: =IFERROR(VLOOKUP(J11, DADOS_RM_EVENTOS_original!E:J, 2, FALSE), "Código não encontrado/Não digitado") -> Código não encontrado/Não digitado | M11: =IFERROR(VLOOKUP(L11, DADOS_RM_EVENTOS_original!K:L, 2, FALSE), "Código não encontrado/Não digitado") -> Código não encontrado/Não digitado
A12: 0004 | B12: 0221 | C12: # desc cartao vale transporte eletronico | D12: D-DESCONTO | E12: 1 | F12: 0047 | G12: Desc. 2a via PASSCARD | I12: =IFERROR(VLOOKUP(H12, DADOS_RM_EVENTOS_original!C:D, 2, FALSE), "Código não encontrado/Não digitado") -> Código não encontrado/Não digitado | K12: =IFERROR(VLOOKUP(J12, DADOS_RM_EVENTOS_original!E:J, 2, FALSE), "Código não encontrado/Não digitado") -> Código não encontrado/Não digitado | M12: =IFERROR(VLOOKUP(L12, DADOS_RM_EVENTOS_original!K:L, 2, FALSE), "Código não encontrado/Não digitado") -> Código não encontrado/Não digitado
A13: 0004 | B13: 0139 | C13: # devol.contribuicao sindical | D13: P-PROVENTO | E13: 1 | F13: 0324 | G13: Reembolso de Contribuicao Sindical | I13: =IFERROR(VLOOKUP(H13, DADOS_RM_EVENTOS_original!C:D, 2, FALSE), "Código não encontrado/Não digitado") -> Código não encontrado/Não digitado | K13: =IFERROR(VLOOKUP(J13, DADOS_RM_EVENTOS_original!E:J, 2, FALSE), "Código não encontrado/Não digitado") -> Código não encontrado/Não digitado | M13: =IFERROR(VLOOKUP(L13, DADOS_RM_EVENTOS_original!K:L, 2, FALSE), "Código não encontrado/Não digitado") -> Código não encontrado/Não digitado
... A56: 0012 | B56: 0967 | C56: 1/3 de Abono Pecuniário | D56: P-PROVENTO | E56: 5 | F56: 0056 | G56: 1/3 Abono de Ferias | I56: =IFERROR(VLOOKUP(H56, DADOS_RM_EVENTOS_original!C:D, 2, FALSE), "Código não encontrado/Não digitado") -> Código não encontrado/Não digitado | K56: =IFERROR(VLOOKUP(J56, DADOS_RM_EVENTOS_original!E:J, 2, FALSE), "Código não encontrado/Não digitado") -> Código não encontrado/Não digitado | M56: =IFERROR(VLOOKUP(L56, DADOS_RM_EVENTOS_original!K:L, 2, FALSE), "Código não encontrado/Não digitado") -> Código não encontrado/Não digitado
A57: 0004 | B57: 0111 | C57: 1/3 DE FÉRIAS | D57: P-PROVENTO | E57: 1 | F57: 0076 | G57: 1/3 Ferias no Mes | H57: 0076 | I57: =IFERROR(VLOOKUP(H57, DADOS_RM_EVENTOS_original!A:D, 2, FALSE), "Código não encontrado/Não digitado") -> 1/3 Ferias no Mes | J57: 0077 | K57: =IFERROR(VLOOKUP(J57, DADOS_RM_EVENTOS_original!A:J, 2, FALSE), "Código não encontrado/Não digitado") -> 1/3 Ferias no Proximo Mes | L57: 0040 | M57: =IFERROR(VLOOKUP(L57, DADOS_RM_EVENTOS_original!A:L, 2, FALSE), "Código não encontrado/Não digitado") -> 1/3 de Ferias (Recibo)
A58: 0015 | B58: 0111 | C58: 1/3 DE FÉRIAS | D58: P-PROVENTO | E58: 2 | F58: 0076 | G58: 1/3 Ferias no Mes | H58: 0076 | I58: =IFERROR(VLOOKUP(H58, DADOS_RM_EVENTOS_original!A:D, 2, FALSE), "Código não encontrado/Não digitado") -> 1/3 Ferias no Mes | J58: 0077 | K58: =IFERROR(VLOOKUP(J58, DADOS_RM_EVENTOS_original!A:J, 2, FALSE), "Código não encontrado/Não digitado") -> 1/3 Ferias no Proximo Mes | L58: 0040 | M58: =IFERROR(VLOOKUP(L58, DADOS_RM_EVENTOS_original!A:L, 2, FALSE), "Código não encontrado/Não digitado") -> 1/3 de Ferias (Recibo)
A59: 0017 | B59: 0111 | C59: 1/3 de Férias | D59: P-PROVENTO | E59: 3 | F59: 0076 | G59: 1/3 Ferias no Mes | H59: 0076 | I59: =IFERROR(VLOOKUP(H59, DADOS_RM_EVENTOS_original!A:D, 2, FALSE), "Código não encontrado/Não digitado") -> 1/3 Ferias no Mes | J59: 0077 | K59: =IFERROR(VLOOKUP(J59, DADOS_RM_EVENTOS_original!A:J, 2, FALSE), "Código não encontrado/Não digitado") -> 1/3 Ferias no Proximo Mes | L59: 0040 | M59: =IFERROR(VLOOKUP(L59, DADOS_RM_EVENTOS_original!A:L, 2, FALSE), "Código não encontrado/Não digitado") -> 1/3 de Ferias (Recibo)
A60: 0005 | B60: 0111 | C60: 1/3 de Férias | D60: P-PROVENTO | E60: 4 | F60: 0076 | G60: 1/3 Ferias no Mes | H60: 0076 | I60: =IFERROR(VLOOKUP(H60, DADOS_RM_EVENTOS_original!A:D, 2, FALSE), "Código não encontrado/Não digitado") -> 1/3 Ferias no Mes | J60: 0077 | K60: =IFERROR(VLOOKUP(J60, DADOS_RM_EVENTOS_original!A:J, 2, FALSE), "Código não encontrado/Não digitado") -> 1/3 Ferias no Proximo Mes | L60: 0040 | M60: =IFERROR(VLOOKUP(L60, DADOS_RM_EVENTOS_original!A:L, 2, FALSE), "Código não encontrado/Não digitado") -> 1/3 de Ferias (Recibo)
A61: 0012 | B61: 0111 | C61: 1/3 de Férias | D61: P-PROVENTO | E61: 5 | F61: 0076 | G61: 1/3 Ferias no Mes | H61: 0076 | I61: =IFERROR(VLOOKUP(H61, DADOS_RM_EVENTOS_original!A:D, 2, FALSE), "Código não encontrado/Não digitado") -> 1/3 Ferias no Mes | J61: 0077 | K61: =IFERROR(VLOOKUP(J61, DADOS_RM_EVENTOS_original!A:J, 2, FALSE), "Código não encontrado/Não digitado") -> 1/3 Ferias no Proximo Mes | L61: 0040 | M61: =IFERROR(VLOOKUP(L61, DADOS_RM_EVENTOS_original!A:L, 2, FALSE), "Código não encontrado/Não digitado") -> 1/3 de Ferias (Recibo)
A62: 0022 | B62: 0111 | C62: 1/3 de Férias | D62: P-PROVENTO | E62: 6 | F62: 0076 | G62: 1/3 Ferias no Mes | H62: 0076 | I62: =IFERROR(VLOOKUP(H62, DADOS_RM_EVENTOS_original!A:D, 2, FALSE), "Código não encontrado/Não digitado") -> 1/3 Ferias no Mes | J62: 0077 | K62: =IFERROR(VLOOKUP(J62, DADOS_RM_EVENTOS_original!A:J, 2, FALSE), "Código não encontrado/Não digitado") -> 1/3 Ferias no Proximo Mes | L62: 0040 | M62: =IFERROR(VLOOKUP(L62, DADOS_RM_EVENTOS_original!A:L, 2, FALSE), "Código não encontrado/Não digitado") -> 1/3 de Ferias (Recibo)
A63: 0004 | B63: 0207 | C63: 1/3 DE FÉRIAS (RESCISÃO) | D63: P-PROVENTO | E63: 1 | F63: 0063 | G63: 1/3 Ferias Rescisao | I63: =IFERROR(VLOOKUP(H63, DADOS_RM_EVENTOS_original!C:D, 2, FALSE), "Código não encontrado/Não digitado") -> Código não encontrado/Não digitado | K63: =IFERROR(VLOOKUP(J63, DADOS_RM_EVENTOS_original!E:J, 2, FALSE), "Código não encontrado/Não digitado") -> Código não encontrado/Não digitado | M63: =IFERROR(VLOOKUP(L63, DADOS_RM_EVENTOS_original!K:L, 2, FALSE), "Código não encontrado/Não digitado") -> Código não encontrado/Não digitado
A64: 0005 | B64: 0207 | C64: 1/3 de Férias (Rescisão) | D64: P-PROVENTO | E64: 4 | F64: 0063 | G64: 1/3 Ferias Rescisao | I64: =IFERROR(VLOOKUP(H64, DADOS_RM_EVENTOS_original!C:D, 2, FALSE), "Código não encontrado/Não digitado") -> Código não encontrado/Não digitado | K64: =IFERROR(VLOOKUP(J64, DADOS_RM_EVENTOS_original!E:J, 2, FALSE), "Código não encontrado/Não digitado") -> Código não encontrado/Não digitado | M64: =IFERROR(VLOOKUP(L64, DADOS_RM_EVENTOS_original!K:L, 2, FALSE), "Código não encontrado/Não digitado") -> Código não encontrado/Não digitado
A65: 0012 | B65: 0207 | C65: 1/3 de Férias (Rescisão) | D65: P-PROVENTO | E65: 5 | F65: 0063 | G65: 1/3 Ferias Rescisao | I65: =IFERROR(VLOOKUP(H65, DADOS_RM_EVENTOS_original!C:D, 2, FALSE), "Código não encontrado/Não digitado") -> Código não encontrado/Não digitado | K65: =IFERROR(VLOOKUP(J65, DADOS_RM_EVENTOS_original!E:J, 2, FALSE), "Código não encontrado/Não digitado") -> Código não encontrado/Não digitado | M65: =IFERROR(VLOOKUP(L65, DADOS_RM_EVENTOS_original!K:L, 2, FALSE), "Código não encontrado/Não digitado") -> Código não encontrado/Não digitado
A66: 0004 | B66: 0987 | C66: 1/3 de Férias Indenizadas | D66: P-PROVENTO | E66: 1 | F66: 0063 | G66: 1/3 Ferias Rescisao | I66: =IFERROR(VLOOKUP(H66, DADOS_RM_EVENTOS_original!C:D, 2, FALSE), "Código não encontrado/Não digitado") -> Código não encontrado/Não digitado | K66: =IFERROR(VLOOKUP(J66, DADOS_RM_EVENTOS_original!E:J, 2, FALSE), "Código não encontrado/Não digitado") -> Código não encontrado/Não digitado | M66: =IFERROR(VLOOKUP(L66, DADOS_RM_EVENTOS_original!K:L, 2, FALSE), "Código não encontrado/Não digitado") -> Código não encontrado/Não digitado
A67: 0017 | B67: 0968 | C67: 1/3 de Férias Proporcionais | D67: P-PROVENTO | E67: 3 | F67: 0063 | G67: 1/3 Ferias Rescisao | I67: =IFERROR(VLOOKUP(H67, DADOS_RM_EVENTOS_original!C:D, 2, FALSE), "Código não encontrado/Não digitado") -> Código não encontrado/Não digitado | K67: =IFERROR(VLOOKUP(J67, DADOS_RM_EVENTOS_original!E:J, 2, FALSE), "Código não encontrado/Não digitado") -> Código não encontrado/Não digitado | M67: =IFERROR(VLOOKUP(L67, DADOS_RM_EVENTOS_original!K:L, 2, FALSE), "Código não encontrado/Não digitado") -> Código não encontrado/Não digitado
A68: 0005 | B68: 0960 | C68: 1/3 de Férias Proporcionais | D68: P-PROVENTO | E68: 4 | F68: 0063 | G68: 1/3 Ferias Rescisao | I68: =IFERROR(VLOOKUP(H68, DADOS_RM_EVENTOS_original!C:D, 2, FALSE), "Código não encontrado/Não digitado") -> Código não encontrado/Não digitado | K68: =IFERROR(VLOOKUP(J68, DADOS_RM_EVENTOS_original!E:J, 2, FALSE), "Código não encontrado/Não digitado") -> Código não encontrado/Não digitado | M68: =IFERROR(VLOOKUP(L68, DADOS_RM_EVENTOS_original!K:L, 2, FALSE), "Código não encontrado/Não digitado") -> Código não encontrado/Não digitado
A69: 0012 | B69: 0959 | C69: 1/3 de Férias Proporcionais | D69: P-PROVENTO | E69: 5 | F69: 0063 | G69: 1/3 Ferias Rescisao | I69: =IFERROR(VLOOKUP(H69, DADOS_RM_EVENTOS_original!C:D, 2, FALSE), "Código não encontrado/Não digitado") -> Código não encontrado/Não digitado | K69: =IFERROR(VLOOKUP(J69, DADOS_RM_EVENTOS_original!E:J, 2, FALSE), "Código não encontrado/Não digitado") -> Código não encontrado/Não digitado | M69: =IFERROR(VLOOKUP(L69, DADOS_RM_EVENTOS_original!K:L, 2, FALSE), "Código não encontrado/Não digitado") -> Código não encontrado/Não digitado
A70: 0022 | B70: 0212 | C70: 1/3 de Férias Proporcionais | D70: P-PROVENTO | E70: 6 | F70: 0063 | G70: 1/3 Ferias Rescisao | I70: =IFERROR(VLOOKUP(H70, DADOS_RM_EVENTOS_original!C:D, 2, FALSE), "Código não encontrado/Não digitado") -> Código não encontrado/Não digitado | K70: =IFERROR(VLOOKUP(J70, DADOS_RM_EVENTOS_original!E:J, 2, FALSE), "Código não encontrado/Não digitado") -> Código não encontrado/Não digitado | M70: =IFERROR(VLOOKUP(L70, DADOS_RM_EVENTOS_original!K:L, 2, FALSE), "Código não encontrado/Não digitado") -> Código não encontrado/Não digitado
A71: 0004 | B71: 0973 | C71: 1/3 de Férias Proporcionais 1 | D71: P-PROVENTO | E71: 1 | F71: 0063 | G71: 1/3 Ferias Rescisao | I71: =IFERROR(VLOOKUP(H71, DADOS_RM_EVENTOS_original!C:D, 2, FALSE), "Código não encontrado/Não digitado") -> Código não encontrado/Não digitado | K71: =IFERROR(VLOOKUP(J71, DADOS_RM_EVENTOS_original!E:J, 2, FALSE), "Código não encontrado/Não digitado") -> Código não encontrado/Não digitado | M71: =IFERROR(VLOOKUP(L71, DADOS_RM_EVENTOS_original!K:L, 2, FALSE), "Código não encontrado/Não digitado") -> Código não encontrado/Não digitado
A72: 0015 | B72: 0973 | C72: 1/3 de Férias Proporcionais 1 | D72: P-PROVENTO | E72: 2 | F72: 0063 | G72: 1/3 Ferias Rescisao | I72: =IFERROR(VLOOKUP(H72, DADOS_RM_EVENTOS_original!C:D, 2, FALSE), "Código não encontrado/Não digitado") -> Código não encontrado/Não digitado | K72: =IFERROR(VLOOKUP(J72, DADOS_RM_EVENTOS_original!E:J, 2, FALSE), "Código não encontrado/Não digitado") -> Código não encontrado/Não digitado | M72: =IFERROR(VLOOKUP(L72, DADOS_RM_EVENTOS_original!K:L, 2, FALSE), "Código não encontrado/Não digitado") -> Código não encontrado/Não digitado
A73: 0017 | B73: 0969 | C73: 1/3 de Férias Vencidas | D73: P-PROVENTO | E73: 3 | F73: 0803 | G73: Adicional 1/3 Ferias Vencidas | I73: =IFERROR(VLOOKUP(H73, DADOS_RM_EVENTOS_original!C:D, 2, FALSE), "Código não encontrado/Não digitado") -> Código não encontrado/Não digitado | K73: =IFERROR(VLOOKUP(J73, DADOS_RM_EVENTOS_original!E:J, 2, FALSE), "Código não encontrado/Não digitado") -> Código não encontrado/Não digitado | M73: =IFERROR(VLOOKUP(L73, DADOS_RM_EVENTOS_original!K:L, 2, FALSE), "Código não encontrado/Não digitado") -> Código não encontrado/Não digitado
A74: 0005 | B74: 0961 | C74: 1/3 de Férias Vencidas | D74: P-PROVENTO | E74: 4 | F74: 0803 | G74: Adicional 1/3 Ferias Vencidas | I74: =IFERROR(VLOOKUP(H74, DADOS_RM_EVENTOS_original!C:D, 2, FALSE), "Código não encontrado/Não digitado") -> Código não encontrado/Não digitado | K74: =IFERROR(VLOOKUP(J74, DADOS_RM_EVENTOS_original!E:J, 2, FALSE), "Código não encontrado/Não digitado") -> Código não encontrado/Não digitado | M74: =IFERROR(VLOOKUP(L74, DADOS_RM_EVENTOS_original!K:L, 2, FALSE), "Código não encontrado/Não digitado") -> Código não encontrado/Não digitado
... A558: 0012 | B558: 0949 | C558: Refeição Mês Anterior | D558: P-PROVENTO | E558: 5 | F558: 0147 | G558: Reembolso Desc. Vale Refeicao | I558: =IFERROR(VLOOKUP(H558, DADOS_RM_EVENTOS_original!C:D, 2, FALSE), "Código não encontrado/Não digitado") -> Código não encontrado/Não digitado | K558: =IFERROR(VLOOKUP(J558, DADOS_RM_EVENTOS_original!E:J, 2, FALSE), "Código não encontrado/Não digitado") -> Código não encontrado/Não digitado | M558: =IFERROR(VLOOKUP(L558, DADOS_RM_EVENTOS_original!K:L, 2, FALSE), "Código não encontrado/Não digitado") -> Código não encontrado/Não digitado
A559: 0004 | B559: 0110 | C559: REMUNERAÇÃO DE FÉRIAS | D559: P-PROVENTO | E559: 1 | F559: 0041 | G559: Ferias no Mes | H559: 0041 | I559: =IFERROR(VLOOKUP(H559, DADOS_RM_EVENTOS_original!A:D, 2, FALSE), "Código não encontrado/Não digitado") -> Ferias no Mes | J559: 0042 | K559: =IFERROR(VLOOKUP(J559, DADOS_RM_EVENTOS_original!A:J, 2, FALSE), "Código não encontrado/Não digitado") -> Ferias no Proximo Mes | L559: 0038 | M559: =IFERROR(VLOOKUP(L559, DADOS_RM_EVENTOS_original!A:L, 2, FALSE), "Código não encontrado/Não digitado") -> Dias de Ferias (Recibo)
A560: 0015 | B560: 0110 | C560: REMUNERAÇÃO DE FÉRIAS | D560: P-PROVENTO | E560: 2 | F560: 0041 | G560: Ferias no Mes | H560: 0041 | I560: =IFERROR(VLOOKUP(H560, DADOS_RM_EVENTOS_original!A:D, 2, FALSE), "Código não encontrado/Não digitado") -> Ferias no Mes | J560: 0042 | K560: =IFERROR(VLOOKUP(J560, DADOS_RM_EVENTOS_original!A:J, 2, FALSE), "Código não encontrado/Não digitado") -> Ferias no Proximo Mes | L560: 0038 | M560: =IFERROR(VLOOKUP(L560, DADOS_RM_EVENTOS_original!A:L, 2, FALSE), "Código não encontrado/Não digitado") -> Dias de Ferias (Recibo)
A561: 0017 | B561: 0110 | C561: Remuneração de Férias | D561: P-PROVENTO | E561: 3 | F561: 0016 | G561: Provento ferias | I561: =IFERROR(VLOOKUP(H561, DADOS_RM_EVENTOS_original!C:D, 2, FALSE), "Código não encontrado/Não digitado") -> Código não encontrado/Não digitado | K561: =IFERROR(VLOOKUP(J561, DADOS_RM_EVENTOS_original!E:J, 2, FALSE), "Código não encontrado/Não digitado") -> Código não encontrado/Não digitado | M561: =IFERROR(VLOOKUP(L561, DADOS_RM_EVENTOS_original!K:L, 2, FALSE), "Código não encontrado/Não digitado") -> Código não encontrado/Não digitado
A562: 0005 | B562: 0110 | C562: Remuneração de Férias | D562: P-PROVENTO | E562: 4 | F562: 0041 | G562: Ferias no Mes | H562: 0041 | I562: =IFERROR(VLOOKUP(H562, DADOS_RM_EVENTOS_original!A:D, 2, FALSE), "Código não encontrado/Não digitado") -> Ferias no Mes | J562: 0042 | K562: =IFERROR(VLOOKUP(J562, DADOS_RM_EVENTOS_original!A:J, 2, FALSE), "Código não encontrado/Não digitado") -> Ferias no Proximo Mes | L562: 0038 | M562: =IFERROR(VLOOKUP(L562, DADOS_RM_EVENTOS_original!A:L, 2, FALSE), "Código não encontrado/Não digitado") -> Dias de Ferias (Recibo)
A563: 0012 | B563: 0110 | C563: Remuneração de Férias | D563: P-PROVENTO | E563: 5 | F563: 0041 | G563: Ferias no Mes | H563: 0041 | I563: =IFERROR(VLOOKUP(H563, DADOS_RM_EVENTOS_original!A:D, 2, FALSE), "Código não encontrado/Não digitado") -> Ferias no Mes | J563: 0042 | K563: =IFERROR(VLOOKUP(J563, DADOS_RM_EVENTOS_original!A:J, 2, FALSE), "Código não encontrado/Não digitado") -> Ferias no Proximo Mes | L563: 0038 | M563: =IFERROR(VLOOKUP(L563, DADOS_RM_EVENTOS_original!A:L, 2, FALSE), "Código não encontrado/Não digitado") -> Dias de Ferias (Recibo)
A564: 0022 | B564: 0110 | C564: Remuneração de Férias | D564: P-PROVENTO | E564: 6 | F564: 0041 | G564: Ferias no Mes | H564: 0041 | I564: =IFERROR(VLOOKUP(H564, DADOS_RM_EVENTOS_original!A:D, 2, FALSE), "Código não encontrado/Não digitado") -> Ferias no Mes | J564: 0042 | K564: =IFERROR(VLOOKUP(J564, DADOS_RM_EVENTOS_original!A:J, 2, FALSE), "Código não encontrado/Não digitado") -> Ferias no Proximo Mes | L564: 0038 | M564: =IFERROR(VLOOKUP(L564, DADOS_RM_EVENTOS_original!A:L, 2, FALSE), "Código não encontrado/Não digitado") -> Dias de Ferias (Recibo)
A565: 0004 | B565: 0112 | C565: REMUNERAÇÃO DE FÉRIAS EM DOBRO | D565: P-PROVENTO | E565: 1 | F565: 0240 | G565: Ferias em Dobro | I565: =IFERROR(VLOOKUP(H565, DADOS_RM_EVENTOS_original!C:D, 2, FALSE), "Código não encontrado/Não digitado") -> Código não encontrado/Não digitado | K565: =IFERROR(VLOOKUP(J565, DADOS_RM_EVENTOS_original!E:J, 2, FALSE), "Código não encontrado/Não digitado") -> Código não encontrado/Não digitado | M565: =IFERROR(VLOOKUP(L565, DADOS_RM_EVENTOS_original!K:L, 2, FALSE), "Código não encontrado/Não digitado") -> Código não encontrado/Não digitado
...

Sheet DADOS_RM_EVENTOS
A1: CODIGO | B1: DESCRICAO | C1: TIPOEVENTO | D1: VALHORDIAREF | E1: NAT_ESOCIAL
A2: CODIGO | B2: DESCRICAO | C2: PROVDESCBASE | D2: VALHORDIAREF | E2: NATRUBRICA_DESCRICAO
A3: 0001 | B3: SALARIO BASE EM HORAS | C3: P | D3: H | E3: 1000 - Salário, vencimento, soldo
A4: 0002 | B4: SALARIO BASE EM DIAS | C4: P | D4: D | E4: 1000 - Salário, vencimento, soldo
A5: 0003 | B5: DESC. INSS SEGURADO | C5: D | D5: V | E5: 9201 - Contribuição Previdenciária
A6: 0004 | B6: DESC. IRRF NA FONTE | C6: D | D6: V | E6: 9203 - Imposto de renda retido na fonte
A7: 0005 | B7: COTA DE SALARIO FAMILIA | C7: P | D7: V | E7: 1409 - Salário família
A8: 0006 | B8: DESC. VALE TRANSPORTE | C8: D | D8: V | E8: 9216 - Desconto de valetransporte
A9: 0007 | B9: ADICIONAL DE PENOSIDADE | C9: P | D9: V | E9: 1214 - Adicional de penosidade
A10: 0008 | B10: DESC. FALTAS (EM DIAS) | C10: D | D10: D | E10: 9209 - Faltas ou atrasos
A11: 0009 | B11: 1ª PARCELA 13º SALARIO | C11: P | D11: V | E11: 5504 - 13º salário ¿ Adiantamento
A12: 0010 | B12: REFLEXO SOBRE ESCALA | C12: P | D12: V | E12: 1012 - Descanso semanal remunerado - DSR e feriado
... A880: 1024 | B880: DEVOLUCAO RECEBIMENTO INDEVIDO(D) | C880: D | D880: V | E880: 9299 - Outros descontos
A1320: NI | B1320: NAO IMPORTAR | C1320: NI
A1321: VC | B1321: VER COM CLIENTE | C1321: VC
A1322: CRIAR | B1322: CRIAR | C1322: CRIAR

Sheet CRIAR_EVENTOS
A1: NOME_DE | B1: TIPO_EVENTO | C1: PARA_EVENTO | D1: PARA_EVENTO
A2: # 1ª VIA CARTÃO HAPVIDA | B2: D-DESCONTO | C2: 1025 | D2: # 1ª VIA CARTÃO HAPVIDA
A3: # OUTROS (PROVENTO) | B3: P-PROVENTO | C3: 1026 | D3: OUTROS PROVENTOS
A4: # TRANSPORTE/ALIMENTACAO | B4: P-PROVENTO | C4: 1027 | D4: # TRANSPORTE/ALIMENTACAO
A5: 2ª VIA CARTAO ALIMENTAÇÃO | B5: D-DESCONTO | C5: 1028 | D5: 2ª VIA CARTAO ALIMENTAÇÃO
A6: 2ª VIA CARTAO REFEICAO | B6: D-DESCONTO | C6: 1029 | D6: 2ª VIA CARTAO REFEICAO
A7: 2ª VIA CARTÃO SUPER CONTA | B7: D-DESCONTO | C7: 1030 | D7: 2ª VIA CARTÃO SUPER CONTA
A8: ADIANT. DE RECESSO | B8: D-DESCONTO | C8: 1031 | D8: ADIANT. DE RECESSO
A9: ADIANTAMENTO DE VT | B9: D-DESCONTO | C9: 1032 | D9: ADIANTAMENTO DE VT
A10: ADICIONAL NOTURNO | B10: P-PROVENTO | C10: 1033 | D10: ADICIONAL NOTURNO
A11: ADICIONAL NOTURNO 21% | B11: P-PROVENTO | C11: 1034 | D11: ADICIONAL NOTURNO 21%
A12: AJUDA CUSTOS ALIMENTAÇ ÃO - CCT SINDICAM | B12: P-PROVENTO | C12: 1035 | D12: AJUDA CUSTOS ALIMENTAÇ ÃO - CCT SINDICAM
A13: ASSITENCIA MEDICA SINDICATO | B13: D-DESCONTO | C13: 1036 | D13: ASSITENCIA MEDICA SINDICATO
